<?xml version="1.0" ?>
<robot name="vertical_robot" xmlns:xacro="http://ros.org/wiki/xacro">

  <material name="dark">
    <color rgba="0.3 0.3 0.3 1.0"/>
  </material>
  
  <link name="world"/>

  <joint name="world_joint" type="fixed">
    <parent link="world"/>
    <child link="base_link"/>
  </joint>

  <link name="base_link">
    <visual>
      <origin xyz="0 0 0.0" rpy="0 0 0"/>
      <geometry>
        <mesh filename="package://vertical_robot_model/meshes/base.stl" scale="0.001 0.001 0.001"/>
      </geometry>
    </visual>
  </link>
  
  <joint name="joint_1" type="prismatic">
    <parent link="base_link"/>
    <child link="link_1"/>
    <origin xyz="0.0 0.0 0.024" rpy="0 0 0"/>
    <limit effort="30" velocity="1.0" lower="-0.05" upper="0.05" />
    <axis xyz="0 1 0"/>
  </joint>

  <link name="link_1">
    <visual>
      <origin xyz="0 0 0.0" rpy="0 0 0"/>
      <geometry>
        <mesh filename="package://vertical_robot_model/meshes/link1.stl" scale="0.001 0.001 0.001"/>
      </geometry>
    </visual>
  </link>
  
  <joint name="joint_2" type="prismatic">
    <parent link="base_link"/>
    <child link="link_2"/>
    <origin xyz="0.0 0.0 -0.024" rpy="0 0 0"/>
    <limit effort="30" velocity="1.0" lower="-0.05" upper="0.05" />
    <axis xyz="1 0 0"/>
  </joint>

  <link name="link_2">
    <visual>
      <origin xyz="0 0 0" rpy="0 0 0"/>
      <geometry>
        <mesh filename="package://vertical_robot_model/meshes/link2.stl" scale="0.001 0.001 0.001"/>
      </geometry>
    </visual>
  </link>
  
  <joint name="joint_1_1" type="prismatic">
    <parent link="link_1"/>
    <child link="link_3_1"/>
    <origin xyz="0.0 0.2133 -0.09" rpy="0 0 0"/>
    <limit effort="30" velocity="1.0" lower="0.0" upper="0.04" />
    <axis xyz="0 0 -1"/>
  </joint>

  <link name="link_3_1">
    <visual>
      <origin xyz="0 0 0" rpy="0 0 0"/>
      <geometry>
        <mesh filename="package://vertical_robot_model/meshes/link3.stl" scale="0.001 0.001 0.001"/>
      </geometry>
    </visual>
  </link>

  <joint name="joint_1_2" type="prismatic">
    <parent link="link_1"/>
    <child link="link_3_2"/>
    <origin xyz="0.0 -0.2133 -0.092" rpy="0 0 3.14"/>
    <limit effort="30" velocity="1.0" lower="0.0" upper="0.04" />
    <mimic joint="joint_1_1" offset="0.0" multiplier="1"/>
    <axis xyz="0 0 -1"/>
  </joint>

  <link name="link_3_2">
    <visual>
      <origin xyz="0 0 0" rpy="0 0 0"/>
      <geometry>
        <mesh filename="package://vertical_robot_model/meshes/link3.stl" scale="0.001 0.001 0.001"/>
      </geometry>
    </visual>
  </link>
  
  <joint name="joint_2_1" type="prismatic">
    <parent link="link_2"/>
    <child link="link_3_3"/>
    <origin xyz="0.2133 0.0 -0.04" rpy="0 0 -1.57"/>
    <limit effort="30" velocity="1.0" lower="0.0" upper="0.04" />
    <axis xyz="0 0 -1"/>
  </joint>

  <link name="link_3_3">
    <visual>
      <origin xyz="0 0 0" rpy="0 0 0"/>
      <geometry>
        <mesh filename="package://vertical_robot_model/meshes/link3.stl" scale="0.001 0.001 0.001"/>
      </geometry>
    </visual>
  </link>
  
  <joint name="joint_2_2" type="prismatic">
    <parent link="link_2"/>
    <child link="link_3_4"/>
    <origin xyz="-0.2133 0.0 -0.04" rpy="0 0 1.57"/>
    <limit effort="30" velocity="1.0" lower="0.0" upper="0.04" />
    <mimic joint="joint_2_1" offset="0.0" multiplier="1"/>
    <axis xyz="0 0 -1"/>
  </joint>

  <link name="link_3_4">
    <visual>
      <origin xyz="0 0 0" rpy="0 0 0"/>
      <geometry>
        <mesh filename="package://vertical_robot_model/meshes/link3.stl" scale="0.001 0.001 0.001"/>
      </geometry>
    </visual>
  </link>

</robot>
